Workbook
Name Accrued_Physical: [2]ImpAnalysis!$I$26
Name Actual_Age: [2]Inputs!$C$159
Name Actual_Taxes: [2]Tax!$G$21
Name Adj_Pro_Assessed_Val: [2]Tax!$K$12
Name AdjCatNo: '[2]IS Grid'!$A$81
Name Ambient_Area: [2]Inputs!$C$96
Name AmtBdgt: [3]OpActuals!$I:$I
Name AMTY1: [3]OpActuals!$C:$C
Name AMTY2: [3]OpActuals!$D:$D
Name AMTY3: [3]OpActuals!$E:$E
Name AMTY4: [3]OpActuals!$F:$F
Name AMTY5: [3]OpActuals!$H:$H
Name AnalysisType: [4]Assumptions!$C$2:$C$3
Name Anchor_1_Name: [2]Inputs!$C$119
Name Anchor_1_SF: [2]Inputs!$C$120
Name Anchor_2_Name: [2]Inputs!$C$121
Name Anchor_2_SF: [2]Inputs!$C$122
Name Anchor_3_Name: [2]Inputs!$C$123
Name Anchor_3_SF: [2]Inputs!$C$124
Name Anchor_4_Name: [2]Inputs!$C$125
Name Anchor_4_SF: [2]Inputs!$C$126
Name Anchor_5_Name: [2]Inputs!$C$127
Name Anchor_5_SF: [2]Inputs!$C$128
Name Anchor_6_Name: [2]Inputs!$C$129
Name Anchor_6_SF: [2]Inputs!$C$130
Name Annual_Mkt_Rent: '[2]Mkt Rent'!$BE$85
Name Appraisal_Fee: [2]Inputs!$C$58
Name Appraiser: [2]Inputs!$C$9
Name Apt.Concessions: '[2]Dir Cap'!$H$8
Name Apt.Concessions.Percent: '[2]Dir Cap'!$E$8
Name Apt.LosstoLease: '[2]Dir Cap'!$H$7
Name Apt.LosstoLease.Percent: '[2]Dir Cap'!$E$7
Name Apt_Row_Cost: [2]Cost!#REF!
Name ARC.Homesites: '[1]ARC Financials'!$F$240
Name ARC.No: [1]Instructions!$B$3
Name ARC.PropAddress: '[1]ARC Property List'!$D$9:$D$67
Name ARC.PropCity: '[1]ARC Property List'!$E$9:$E$67
Name ARC.PropCode: '[1]ARC Property List'!$B$9:$B$67
Name ARC.PropName: '[1]ARC Property List'!$C$9:$C$67
Name ARC.PropState: '[1]ARC Property List'!$F$9:$F$67
Name ARC.PropZip: '[1]ARC Property List'!$G$9:$G$67
Name ARI: '[2]Dir Cap'!$H$9
Name ArrTot: [6]Assumptions!$F$9:$G$21
Name ArrTotal: [4]Assumptions!$F$9:$G$21
Name As_Is_Value: [2]Values!$M$21
Name bbDateOfValueEffectiveDate: '[7]Valuation Scenarios'!$D$85
Name bbDateReport: [7]Assignment!$B$44
Name bbMarketValues: '[7]Valuation Scenarios'!$D$76
Name bbPropertyOwner: [7]Assignment!$B$27
Name bbValuationType: '[7]Valuation Scenarios'!$D$79
Name bbValueConditionScen1: '[3]Valuation Scenarios'!$B$8
Name bbValueDateScen1: '[3]Valuation Scenarios'!$B$5
Name bbValueInterestScen1: '[3]Valuation Scenarios'!$B$7
Name bbValueNameScen1: '[3]Valuation Scenarios'!$B$4
Name Building_Area: [2]Inputs!$C$146
Name Building_Class_List: [2]InputsRangeNames!$J$4:$J$8
Name Building_Class_Value: [2]InputsRangeNames!$J$2
Name Building_Class_Value_List: [2]InputsRangeNames!$I$4:$I$8
Name caDeferredMaint: [3]Cost!$F$44
Name caLandValueRND: [3]LSaleAdj!$E$48

Sheet Property Info
A1: Building Labels | B1: =IF($B$4>=2,"Building 1","") | C1: =IF($B$4=1,"Bldg 1",IF($B$4>=2,"Bldg 2","")) | D1: =IF($B$4>=3,"Bldg 3","") | E1: =IF($B$4>=4,"Bldg 4","") | F1: =IF($B$4>=5,"Bldg 5","") | G1: =IF($B$4>=6,"Bldg 6","") | H1: =IF($B$4>=7,"Bldg 7","") | I1: =IF($B$4>=8,"Bldg 8","") | J1: =IF($B$4>=9,"Bldg 9","") | K1: =IF($B$4>=10,"Bldg 10","") | L1: =IF($B$4>=11,"Bldg 11","") | M1: =IF($B$4>=12,"Bldg 12","")
A2: Account
A3: Occ. Code
A4: Number of Buildings
A5: GBA
A6: Footprint
A7: NRA
A8: SF Basis | B8: GBA
A9: Year Built
A10: Condition
A11: Year/Condition | B11: 1999/Average
A12: Site Size
A13: Acres | B13: =B12/43560
A14: Coverage Ratio | B14: =B5/B12
A15: Office %
A16: Type
A17: Address
A18: City
A19: County | B19: Adams County
A20: Assumed Occupancy
A21: Assessor's Assigned Value
A22: Petitioner's Value
A23: Recent Sale Date
A24: Recent Sale Price
A25: Sale Type
A26: Value Premise | B26: Fee Simple
A27: Date of Value
A28: Report Date
A29: Hearing Date
A30: Zoning
A31: Zoning Authority | B31: Adams County

Sheet FE
A1: Note: | B1: FILL ONLY HIGHLIGHTED CELLS
B3: EXECUTIVE SUMMARY
B4: Account Number | C4: ='Property Info'!B2
B5: Address | C5: ='Property Info'!B17
B6: County | C6: ='Property Info'!B19
B7: City, State | C7: ='Property Info'!B18
B8: Effective Date | C8: ='Property Info'!B27
B9: Appraisal Date | C9: ='Property Info'!B28
B10: Hearing Date | C10: ='Property Info'!B29
B12: Property Type | C12: ='Property Info'!B16
B13: Property Size
B14: ='Property Info'!B8 | C14: =IF(B14="GBA", 'Property Info'!B5,IF(B14="NRA",'Property Info'!B7,'Property Info'!B5))
B15: Number of Buildings | C15: ='Property Info'!B4
B16: Year Built/Condition | C16: ='Property Info'!B11
B17: Condition | C17: ='Property Info'!B10
B18: Site Size (SF) | C18: ='Property Info'!B12
B19: Property Rights Appraised | C19: ='Property Info'!B26
B20: Assumed Occupancy | C20: ='Property Info'!B20
B21: Stabilized Occupancy | C21: ='Income Approach'!D22
D23: PETITION SCENARIO
E24: $ | F24: $/SF
D25: Assessor's Assigned Value | E25: ='Basic Sales Grid'!D51 | F25: =E25/C14
D26: Petitioner’s Requested Value | E26: ='Basic Sales Grid'!D52 | F26: =E26/C14
G28: APPRAISAL INFORMATION
G29: Intended User | H29: Adams County Board of Equalization, Adams County Attorney, Colorado Board of Assessment Appeals
H30: =clCompanyAddressStreet1&", "&clCompanyAddressStreet2
H31: =clCompanyAddressCity&", "&clCompanyAddressState&" "&clCompanyAddressZip
G32: Intended User(s) | H32: =H29
G33: Intended Use | H33: Aid in tax appeal decision
G34: Values Concluded | H34: Retrospective Market Value
G35: Property Rights Appraised / Premise
G36: Premise Summary
G37: Date of Inspection
G38: Report Date | H38: ='Property Info'!B28
G39: Marketing Time | H39: 12 months
G40: Exposure Time | H40: 12 months
G41: Owner of Record
G42: Property Contact(s)
G43: Most Probable Purchaser | H43: =pdMostProbablePurchaser
G44: Highest and Best Use
...

Sheet Market Neighborhood
B2: MARKET DATA
B3: Surrounding Area | C3: Industrial | D3: Market Trend | E3: Growth
B4: Overall Real Estate Values | C4: Increasing | D4: Neighborhood Vacancy
B5: Predominant Property Use(s) | C5: Industrial Neighborhood Retail Lodging | D5: Estimated Marketing | E5: 12 months
D6: Estimated Exposure | E6: 12 months
B7: Market Subsector(s) | F7: ←Change this
B8: Vacancy - CoStar - Industrial 20,000 SF-50,000 SF | F8: ←From Income
D9: =D7 | F9: ←Change This
B10: Vacancy - CoStar - Industrial 20,000 SF-50,000 SF | F10: ←From Income
F11: NEIGHBORHOOD DATA
F12: Market Area Comments
F13: Surrounding Uses | H13: Industrial Lots
H14: Light Industrial
H15: Industrial Storage Lot
H16: Light Industrial
F17: Property Contact Interview | G17: =clInspectionContactName
I18: CHANGE → | J18: Average Sale Price - Denver Market Industrial - 10,000 SF-50,000 SF | N18: Average Sale Price - Adams County Industrial - 10,000 SF-50,000 SF
J19: Period | K19: Avg. Price ($/SF) | L19: % Change - Q2 2020 | M19: ←CHANGE → | N19: Period | O19: Avg. Price ($/SF) | P19: % Change - Q2 2020

Sheet Site Information
B2: SITE DESCRIPTION OVERVIEW
B4: Location | C4: =FE!U99
B5: Account Number | C5: =FE!U103
B6: Legal Description | C6: =FE!U106
B7: Site Area
B8: Primary Site | C8: =FE!U108 | D8: =FE!V108
B9: Excess Land | C9: =FE!U109 | D9: =FE!V109
B10: Surplus Land | C10: =FE!U110 | D10: =FE!V110
B11: Total | C11: =FE!U111 | D11: =FE!V111
B12: Configuration
B13: Topography | C13: Generally Level
B14: Drainage | C14: Appears adequate
B15: Utilities/Municipal Services | C15: Typical utilities and municipal services available to site.
B16: Floodplain | C16: Zone | D16: Map | E16: Date
C17: Zone X (Unshaded) | I17: Zone A | J17: Zone X (Shaded)
C18: Zone X (unshaded) is a Non-Special Flood Hazard Area (NSFHA) of minimal flood hazard, usually depicted on Flood Insurance Rate Maps (FIRM) as above the 500-year flood level. This is an area in a low to moderate risk flood zone that is not in any immediate danger from flooding caused by overflowing rivers or hard rains. In communities that participate in the National Flood Insurance Program (NFIP), flood insurance is available to all property owners and renters in this zone.
B19: Census Tract No. | C19: =pdCensusTract
B21: SITE DESCRIPTION OVERVIEW - CONTINUED
B22: Soil/Subsoil Conditions | C22: We did not receive nor review a soil report. However, we assume that the soil's load-bearing capacity is sufficient to support existing structure(s). We did not observe any evidence to the contrary during our physical inspection of the property.
B23: Environmental Concerns | C23: No unusual conditions observed. No studies provided. Site is assumed to be free of any environmental concerns.
B24: Land Use Restrictions
B25: Hazards Nuisances | C25: None noted
B26: Frontage
B27: Access
B28: Visibility
B29: Surrounding Land Uses | C29: Light to medium-intensity industrial
B30: Enterprise Zone | C30: None noted
B31: Traffic Counts
B32: Transportation Facilities
B33: Comments
H35: ZONING
H36: Designation
H37: Description | I37: Industrial-1 (Light Industrial)
H38: Zoning Intent | I38: The purpose of the Industrial‐1 District is to provide a general commercial and limited industrial district designed to provide for a variety of compatible business, warehouse, wholesale, offices and very limited industrial uses. Special uses are permitted in an Industrial‐1 District, subject to the issuance of a Special Use Permit from the Board of Adjustment. Temporary uses are permitted in the Industrial‐1 District, subject to the issuance of a Temporary Use Permit from the Director of Community and Economic Development.
H39: Compliance | I39: The subject is a legal confirming use in the I-1 zoning designation.
H40: ZONING REQUIREMENTS
H41: Min. Lot Size: | I41: 1 Acre
H42: Min. Lot Width: | I42: 100 Feet
H43: Setbacks:
H44: Front | I44: 25 Feet
...

Sheet Improvements
B2: =IF(OR(pdGenPropUse2="",pdGenPropUse2=0),"GENERAL DESCRIPTION OVERVIEW", "GENERAL DESCRIPTION OVERVIEW - "&UPPER(pdGenPropUse))
B3: Address | C3: ='Property Info'!B17
C4: ='Property Info'!B18
B5: Property Description | C5: =FE!U100
B6: Year Built | C6: ='Property Info'!B9
B7: Year Renovated | C7: =FE!U116
B8: Number of Buildings | C8: =FE!U120
B9: Number of Stories
B10: Total Number of Units | C10: =FE!U126
B11: Building Construction Class
B12: Net Rentable Area | C12: =FE!U124
B13: Gross Leasable Area | C13: =FE!U122
B14: + Clubhouse | C14: =pdBldgAreaClubhouse
B15: + Others(s) | C15: =pdBldgAreaOther
B16: Mezzanine Area
B17: Building Footprint | C17: ='Property Info'!B6
B18: Bay Depth | C18: =pdBayDepth
B19: LEED Ratio | C19: =pdLEEDRating
B20: Floor-Area Ratio | C20: =pdFAR
B21: Elevator(s) | C21: None
B22: Ceiling Heights
B23: Utility Metering | C23: Master metered
B24: Density (Units/Acre) | C24: =C10/'Site Information'!C11
B25: Coverage Ratio | C25: =C17/'Site Information'!C11
B26: Land-to-Building Ratio | C26: ='Site Information'!C11/Improvements!C13
B27: Ingress/Egress
B28: Percentage Office Build-Out | C28: ='Property Info'!B15
B29: Clear Height
B30: Power | C30: Assumed adequate for industrial use.
B31: Loading Doors
B32: Dock High
B33: Roll-Up
B34: Rail Access | C34: None
B35: Storage Yard
B36: Truck Court
B37: Parking
B38: Surface Parking Spaces
B39: Other | C39: 0
B40: Garages | C40: 0
B41: Total Parking Spaces | C41: =SUM(C38:C40)
...

Sheet H&BU
C1: NOTE: Most of the below text is standard boilerplate and should remain the same. Read through and change only the descriptions as they pertain to your property.
B3: AS IF VACANT
B4: Legally | C4: Legal restrictions include deed restrictions, CC&R’s, lease encumbrances, zoning requirements, building codes, historic district controls and environmental regulations, and were previously analyzed to determine legally permitted uses. Legally, the subject is zoned I-1 (Light Industrial). The purpose of the Industrial‐1 District is to provide a general commercial and limited industrial district designed to provide for a variety of compatible business, warehouse, wholesale, offices and very limited industrial uses. Special uses are permitted in an Industrial‐1 District, subject to the issuance of a Special Use Permit from the Board of Adjustment. Temporary uses are permitted in the Industrial‐1 District, subject to the issuance of a Temporary Use Permit from the Director of Community and Economic Development. Allowable uses include but are not limited to storage, distribution, wholesale, office/flex, warehousing, maintenance, and light manufacturing.
B5: Physically | C5: Size, shape, topography, soil condition, availability of utilities, transportation access, surrounding uses, and locational characteristics were previously analyzed to determine which legal land uses are physically possible and which are best to conform to the physical and locational aspects of the site and its setting with respect to the neighborhood and community. Overall, the physical site attributes result in adequate utility, and the property could be developed with a variety of legally-conforming uses. Given the surrounding uses and location, the site is best suited for light industrial use.
B6: Financially | C6: Financial feasibility is determined by the relationship of supply and demand for the legally probable land uses versus the cost to create them. The market analysis section reveals that retail uses in the subject's market are generally stabilized. Ongoing industrial development during the period in question throughout the market area serve as direct evidence that new industrial development was financially feasible at this time. Comparisons of rental rates, operating expenses and construction costs indicate the subject property would have been capable of providing an adequate return on investment to warrant new industrial development in the market. This assertion is supported by the fact that the property has the potential to generate rental income as shown in the income approach. Therefore, retail use is considered financially feasible.
B7: Maximally | C7: The final test of highest and best use of the site as vacant is that the use be maximally productive, yielding the highest return to the land. In order to determine the maximally productive use, a comparison of rental rates, occupancy, operating expenses, and rates of return for the financially feasible uses have been made. Based on this analysis, light industrial use renders the highest residual land value; therefore, light industrial development on the subject's site is the maximally productive use of the subject as vacant.
B11: AS IMPROVED
B12: Legally | C12: The subject is a legal conforming use in the I-1 zoning district. No other known legal encumbrances exists that limit use or function on the improved property.
B13: Physically
B14: Financially | C14: Financial feasibility as an income-producing investment is based on the amount of rental income it can generate net of the required operating expenses. If the resulting net operating income motivates continued operation, then the land is being put to a productive and financially feasible use. The subject is capable of producing positive net cash flow to an investor. The existing improvements provide contributory value to the site, and there is no alternate use that would result in a greater value. Therefore, utilization of the existing improvements is financially feasible.
B15: Maximally | C15: The maximally productive use should conform to neighborhood trends and be consistent with existing nearby land uses. The single use that produces the greatest return on investment and usually the highest price and value is typically the highest and best use. As shown in the applicable valuation sections, properties like the subject have been acquired and continue to be used for retail use. None of the comparable properties were acquired for conversion to an alternative use. This provides evidence suggesting that the current retail use is maximally productive.

Sheet Final Value
C2: VALUE INDICATIONS
C3: As Is - Land Value Only
C4: Sales Comparison Approach | D4: ='Land Sales'!#REF! | E4: =D4/'Property Info'!B12 | F4: Per Square Foot (LA)
C5: Value Conclusion - As Is | D5: =D4 | E5: =E4 | F5: =F4
C6: As Is - Retrospective Market Value - Fee Simple Estate
C7: Cost Approach | D7: Not Developed
C8: Sales Comparison Approach | D8: ='Basic Sales Grid'!D46 | E8: =D8/FE!$C$14 | F8: =FE!B14
C9: Income Capitalization Approach
C10: Direct Capitalization | D10: ='Income Approach'!C65 | E10: =D10/FE!$C$14 | F10: =F8
C11: Approach Reliance | D11: =IF(FE!B14="GBA",'Final Value'!C8,'Final Value'!C9)
C12: Value Conclusion | D12: =D10 | E12: =D12/FE!$C$14 | F12: =F8
C13: As Is
C14: Sales Comparison Approach | D14: =#REF! | E14: =#REF! | F14: Per Square Foot (GBA)
C15: Income Capitalization Approach
C16: Direct Capitalization | F16: =F14
C17: Approach Reliance | D17: Sales Comparison Approach
C18: ="Value Conclusion - "&PROPER(bbValueConditionScen1)&"" | D18: =D14 | E18: =E14 | F18: =F14
C19: Exposure Time | D19: 12 months
C20: Marketing Time | D20: 12 months
G21: MARKET VALUE CONCLUSION
G22: Appraisal Premise | H22: Interest Appraised | I22: Date of Value | J22: Value Conclusion
G23: Retrospective Market Value | H23: Fee Simple | I23: ='Property Info'!B27 | J23: =D12
G26: 6 MONTH LIQUIDATION VALUE CONCLUSION
G27: Appraisal Premise | H27: Interest Appraised | I27: Date of Value | J27: Value Conclusion
G28: =bbValueNameScen1 | H28: Fee Simple
G30: HYPOTHETICAL MARKET VALUE CONCLUSION (UNDERLYING LAND ONLY)
G31: Appraisal Premise | H31: Interest Appraised | I31: Date of Value | J31: Value Conclusion
G32: As If Vacant | H32: Fee Simple
G34: PROSPECTIVE MARKET VALUE CONCLUSION
G35: Appraisal Premise | H35: Interest Appraised | I35: Date of Value | J35: Value Conclusion
G36: Upon Completion | H36: Fee Simple | J36: =D12

Sheet Land Sales
B1: NOTES:
B2: Change Highlighted fields only
B3: Change highlighted areas to WHITE when complete
B4: Check all cells for accuracy after completing
B5: Remember to spell check every worksheet as you go.
B7: COMPARABLE SALE ADJUSTMENT GRID
C8: Subject | D8: Sale 1 | F8: Sale 2 | H8: Sale 3 | J8: Sale 4 | L8: Sale 5
B9: Address | C9: ='Property Info'!B17
B10: City, State | C10: ='Property Info'!B18
B11: Account/Parcel Number | C11: ='Property Info'!B2
B12: Property Type | C12: Industrial Land | E12: Industrial Land | G12: Industrial Land | I12: Industrial Land | K12: Industrial Land | L12: Commercial Land
B13: Sale Date | C13: N/A
B14: Sale Price | C14: N/A
B15: Listing Price | C15: N/A | E15: Not Reported | G15: 1224040 | I15: 1600000 | K15: Not Reported | L15: 500000
B16: Days On Market | C16: N/A | E16: Not Reported | G16: 1117 | I16: 259 | K16: Not Reported | L16: 725
B17: Data Source | C17: Assessor, appraiser measurements | E17: Costar, Assessor Data, Deed, Troy DeVos (Buyer Representative) | G17: CoStar, Assessor Data, Listing Broker (Phil Foster & Co.) | I17: CoStar, Assessor Data, Listing Broker (Mark Goodman/Goodman Commercial) | K17: CoStar, Denver Assessor, Deed, Loan | L17: CoStar, Assessor, Listing
B18: Grantor | C18: TBD
B19: Grantee | C19: TBD
B20: Site Size (SF) | C20: ='Property Info'!B12
B21: Zoning | C21: ='Property Info'!B30 | E21: B-3 (Business/Commercial) | G21: PUD-I (Industrial) | I21: I-2 (General Industrial) | K21: I-B (General Industrial) | L21: B-2
B22: Comments | C22: Industrial land
B23: Unadjusted Price Per SF | E23: =E14/E20 | G23: =G14/G20 | I23: =I14/I20 | K23: =K14/K20 | M23: =L15/L20
B24: Quantified Adjustments
B25: Property Rights Conveyed | C25: Fee Simple | D25: Fee Simple | E25: 0 | F25: Fee Simple | G25: 0 | H25: Fee Simple | I25: 0 | J25: Fee Simple | K25: 0 | L25: Fee Simple
B26: Property Rights Conveyed Adjusted | E26: =IF(LEFT(CELL("format",E25),1)="P",E23*(1+E25),IF(LEFT(CELL("format",E25),1)="C",E23+E25)) | G26: =IF(LEFT(CELL("format",G25),1)="P",G23*(1+G25),IF(LEFT(CELL("format",G25),1)="C",G23+G25)) | I26: =IF(LEFT(CELL("format",I25),1)="P",I23*(1+I25),IF(LEFT(CELL("format",I25),1)="C",I23+I25)) | K26: =IF(LEFT(CELL("format",K25),1)="P",K23*(1+K25),IF(LEFT(CELL("format",K25),1)="C",K23+K25)) | M26: =IF(LEFT(CELL("format",M25),1)="P",M23*(1+M25),IF(LEFT(CELL("format",M25),1)="C",M23+M25))
B27: Financing | C27: N/A | D27: Market-Based | E27: 0 | F27: Market-Based | G27: 0 | H27: Market-Based | I27: 0 | J27: Market-Based | K27: 0 | L27: Market-Based | M27: 0
B28: Financing Adjusted | E28: =IF(LEFT(CELL("format",E27),1)="P",E26*(1+E27),IF(LEFT(CELL("format",E27),1)="C",E26+E27)) | G28: =IF(LEFT(CELL("format",G27),1)="P",G26*(1+G27),IF(LEFT(CELL("format",G27),1)="C",G26+G27)) | I28: =IF(LEFT(CELL("format",I27),1)="P",I26*(1+I27),IF(LEFT(CELL("format",I27),1)="C",I26+I27)) | K28: =IF(LEFT(CELL("format",K27),1)="P",K26*(1+K27),IF(LEFT(CELL("format",K27),1)="C",K26+K27)) | M28: =IF(LEFT(CELL("format",M27),1)="P",M26*(1+M27),IF(LEFT(CELL("format",M27),1)="C",M26+M27)) | R28: =0.25*J20
B29: Terms/Conditions of Sale | C29: N/A | D29: None | E29: 0 | F29: None | G29: 0 | H29: None | I29: 0 | J29: None | K29: 0 | L29: None | M29: 0
B30: Terms/Conditions of Sale Adjusted | E30: =IF(LEFT(CELL("format",E29),1)="P",E28*(1+E29),IF(LEFT(CELL("format",E29),1)="C",E28+E29)) | G30: =IF(LEFT(CELL("format",G29),1)="P",G28*(1+G29),IF(LEFT(CELL("format",G29),1)="C",G28+G29)) | I30: =IF(LEFT(CELL("format",I29),1)="P",I28*(1+I29),IF(LEFT(CELL("format",I29),1)="C",I28+I29)) | K30: =IF(LEFT(CELL("format",K29),1)="P",K28*(1+K29),IF(LEFT(CELL("format",K29),1)="C",K28+K29)) | M30: =IF(LEFT(CELL("format",M29),1)="P",M28*(1+M29),IF(LEFT(CELL("format",M29),1)="C",M28+M29))
B31: Expenditures After Sale | C31: N/A | D31: None | E31: 0 | F31: None | G31: 0 | H31: None | I31: 0 | J31: None | K31: 0 | L31: None | M31: 0
B32: Expenditures After Sale Adjusted | E32: =IF(LEFT(CELL("format",E31),1)="P",E30*(1+E31),IF(LEFT(CELL("format",E31),1)="C",E30+E31)) | G32: =IF(LEFT(CELL("format",G31),1)="P",G30*(1+G31),IF(LEFT(CELL("format",G31),1)="C",G30+G31)) | I32: =IF(LEFT(CELL("format",I31),1)="P",I30*(1+I31),IF(LEFT(CELL("format",I31),1)="C",I30+I31)) | K32: =IF(LEFT(CELL("format",K31),1)="P",K30*(1+K31),IF(LEFT(CELL("format",K31),1)="C",K30+K31)) | M32: =IF(LEFT(CELL("format",M31),1)="P",M30*(1+M31),IF(LEFT(CELL("format",M31),1)="C",M30+M31))
B33: Market Conditions | C33: N/A | D33: =D13 | E33: 0 | F33: =F13 | G33: 0 | H33: =H13 | I33: 0 | J33: =J13 | K33: 0 | L33: TBD | M33: 0
B34: Market Conditions Adjusted | E34: =IF(LEFT(CELL("format",E33),1)="P",E32*(1+E33),IF(LEFT(CELL("format",E33),1)="C",E32+E33)) | G34: =IF(LEFT(CELL("format",G33),1)="P",G32*(1+G33),IF(LEFT(CELL("format",G33),1)="C",G32+G33)) | I34: =IF(LEFT(CELL("format",I33),1)="P",I32*(1+I33),IF(LEFT(CELL("format",I33),1)="C",I32+I33)) | K34: =IF(LEFT(CELL("format",K33),1)="P",K32*(1+K33),IF(LEFT(CELL("format",K33),1)="C",K32+K33)) | M34: =IF(LEFT(CELL("format",M33),1)="P",M32*(1+M33),IF(LEFT(CELL("format",M33),1)="C",M32+M33))
B35: Total Quantified Adjustment | E35: =IFERROR(TEXT(E34-E23,"$#,##0.00")&CHAR(10)&" or "&CHAR(10)&TEXT((E34-E23)/E23,"0.00%"),0) | G35: =IFERROR(TEXT(G34-G23,"$#,##0.00")&CHAR(10)&" or "&CHAR(10)&TEXT((G34-G23)/G23,"0.00%"),0) | I35: =IFERROR(TEXT(I34-I23,"$#,##0.00")&CHAR(10)&" or "&CHAR(10)&TEXT((I34-I23)/I23,"0.00%"),0) | K35: =IFERROR(TEXT(K34-K23,"$#,##0.00")&CHAR(10)&" or "&CHAR(10)&TEXT((K34-K23)/K23,"0.00%"),0) | M35: =IFERROR(TEXT(M34-M23,"$#,##0.00")&CHAR(10)&" or "&CHAR(10)&TEXT((M34-M23)/M23,"0.00%"),0)
B36: Quantitatively Adjusted Price | E36: =E34 | G36: =G34 | I36: =I34 | K36: =K34 | M36: =M34
B37: Location | C37: ='Basic Sales Grid'!D28 | D37: Average
B38: Distance from Subject | C38: N/A
B39: Surrounding Land Uses | C39: Retail, residential, developable land
B40: Quality/Condition of Surrounding Area | C40: Average to New
B41: Access to Commercial Services/Amenities | C41: Good
...

Sheet M&S Inputs
B1: MARSHALL AND SWIFT (MVS) REFERENCE ENGINE -- June 2024 Ed. (Section 99/98 multiplier inserts dated Jan 2025)
B2: ALL WORKING INPUTS LIVE ON THE 'COST APPROACH' TAB -- this sheet is locked MVS reference/lookup data only. Go to Cost Approach to value a property.
B4: CURRENT RESULT (mirrors the 'Cost Approach' tab)
B5: Total Replacement Cost New (RCN) | C5: ='Cost Approach'!G51
B6: Depreciated Value of Improvements | C6: ='Cost Approach'!G64
B7: Plus: Land Value | C7: ='Cost Approach'!G67
B8: INDICATED VALUE BY COST APPROACH | C8: ='Cost Approach'!G70
B11: MVS QUICK-REFERENCE TABLES -- DO NOT EDIT (sourced &amp; verified from the licensed MVS June 2024 edition; Sec.99/98 multiplier inserts dated Jan 2025)
B13: REFERENCE 1 -- Class of Construction Indicators (MVS Section 1, pp.4-9)
B14: Class | C14: Frame | D14: Floor | E14: Roof | F14: Walls
B15: A | C15: Structural steel columns and beams, fireproofed with masonry, concrete, plaster, or other noncombustible material. | D15: Concrete or concrete on steel deck, fireproofed. | E15: Formed concrete, precast slabs, concrete or gypsum on steel deck, fireproofed. | F15: Nonbearing curtain walls, masonry, concrete, metal and glass panels, stone, steel studs and masonry, tile or stucco, etc.
B16: B | C16: Reinforced concrete columns and beams. | D16: Concrete or concrete on steel deck, fireproofed. | E16: Formed concrete, precast slabs, concrete or gypsum on steel deck, fireproofed. | F16: Nonbearing curtain walls, masonry, concrete, metal and glass panels, stone, steel studs and masonry, tile or stucco, etc.
B17: C | C17: Masonry or concrete load-bearing walls with or without pilasters. Masonry, concrete or curtain walls with full or partial open steel, wood, or concrete frame. | D17: Wood or concrete plank on wood or steel floor joists, or concrete slab on grade. | E17: Wood or steel joists with wood or steel deck. Concrete plank. | F17: Brick, concrete block, or tile masonry, tilt-up, formed concrete, nonbearing curtain walls.
B18: D | C18: Wood or steel studs in bearing wall, full or partial open wood or steel frame, primarily combustible construction. | D18: Wood or steel floor joists or concrete slab on grade. | E18: Wood or steel joists with wood or steel deck. | F18: Almost any material except bearing or curtain walls of solid masonry or concrete. Generally combustible construction.
B19: S | C19: Metal bents, columns, girders, purlins and girts without fireproofing, incombustible construction. | D19: Wood or steel deck on steel floor joists, or concrete slab on grade. | E19: Steel or wood deck on steel joists. | F19: Metal skin or sandwich panels. Generally incombustible.
B21: REFERENCE 2 -- Quality Tier Definitions (MVS Section 1, pp.10-12)
B22: Quality | C22: Description
B23: Low Cost | C23: Constructed to minimum code requirements, little regard for architectural appearance, minimum investment, little ornamentation, minimal/low-quality interior finish.
B24: Average | C24: Largest group of buildings constructed (~50% of all buildings). Designed for maximum economic potential without pride-of-ownership amenities. Good standard code construction, simple ornamentation and finishes.
B25: Good | C25: Designed for good appearance, comfort and convenience with an element of prestige. Higher-quality ornamental treatment, interiors designed for upper-class rentals, better lighting and mechanical work.
B26: Excellent | C26: Prestige buildings. Part of cost is attributable to pride of ownership. Expensive finishes and fixtures; built for established professionals/institutions or high-profile tenants.
B28: REFERENCE 3 -- Occupancy Base Cost Tables (Calculator Method, $/SF)
B29: Occupancy Name | C29: Occ. Code | D29: Section | E29: Page | F29: Class | G29: Quality | H29: $/SF | I29: Lookup Key | J29: Story Tbl | K29: Sprinkler Tbl | L29: Elevator Tbl | M29: Citation
B30: Storage Warehouses | C30: 406 | D30: 14 | E30: 26 | F30: A | G30: Good | H30: 137 | I30: =B30&"~"&F30&"~"&G30 | J30: 14 | K30: 14 | L30: 14 | M30: MVS Sec.14 p.26
B31: Storage Warehouses | C31: 406 | D31: 14 | E31: 26 | F31: A | G31: Average | H31: 101 | I31: =B31&"~"&F31&"~"&G31 | J31: 14 | K31: 14 | L31: 14 | M31: MVS Sec.14 p.26
B32: Storage Warehouses | C32: 406 | D32: 14 | E32: 26 | F32: A | G32: Low Cost | H32: 79.5 | I32: =B32&"~"&F32&"~"&G32 | J32: 14 | K32: 14 | L32: 14 | M32: MVS Sec.14 p.26
B33: Storage Warehouses | C33: 406 | D33: 14 | E33: 26 | F33: B | G33: Good | H33: 121 | I33: =B33&"~"&F33&"~"&G33 | J33: 14 | K33: 14 | L33: 14 | M33: MVS Sec.14 p.26
B34: Storage Warehouses | C34: 406 | D34: 14 | E34: 26 | F34: B | G34: Average | H34: 88 | I34: =B34&"~"&F34&"~"&G34 | J34: 14 | K34: 14 | L34: 14 | M34: MVS Sec.14 p.26
B35: Storage Warehouses | C35: 406 | D35: 14 | E35: 26 | F35: B | G35: Low Cost | H35: 69 | I35: =B35&"~"&F35&"~"&G35 | J35: 14 | K35: 14 | L35: 14 | M35: MVS Sec.14 p.26
B36: Storage Warehouses | C36: 406 | D36: 14 | E36: 26 | F36: C | G36: Excellent | H36: 134 | I36: =B36&"~"&F36&"~"&G36 | J36: 14 | K36: 14 | L36: 14 | M36: MVS Sec.14 p.26
B37: Storage Warehouses | C37: 406 | D37: 14 | E37: 26 | F37: C | G37: Good | H37: 86.5 | I37: =B37&"~"&F37&"~"&G37 | J37: 14 | K37: 14 | L37: 14 | M37: MVS Sec.14 p.26
B38: Storage Warehouses | C38: 406 | D38: 14 | E38: 26 | F38: C | G38: Average | H38: 61 | I38: =B38&"~"&F38&"~"&G38 | J38: 14 | K38: 14 | L38: 14 | M38: MVS Sec.14 p.26
B39: Storage Warehouses | C39: 406 | D39: 14 | E39: 26 | F39: C | G39: Low Cost | H39: 43 | I39: =B39&"~"&F39&"~"&G39 | J39: 14 | K39: 14 | L39: 14 | M39: MVS Sec.14 p.26
B40: Storage Warehouses | C40: 406 | D40: 14 | E40: 26 | F40: CMILL | G40: Good | H40: 119 | I40: =B40&"~"&F40&"~"&G40 | J40: 14 | K40: 14 | L40: 14 | M40: MVS Sec.14 p.26
B41: Storage Warehouses | C41: 406 | D41: 14 | E41: 26 | F41: CMILL | G41: Average | H41: 82 | I41: =B41&"~"&F41&"~"&G41 | J41: 14 | K41: 14 | L41: 14 | M41: MVS Sec.14 p.26
... B289: Hotels, Limited Service | C289: 595 | D289: 11 | E289: 22 | F289: S | G289: Average | H289: 135 | I289: =B289&"~"&F289&"~"&G289 | J289: 11 | K289: 11 | L289: 11 | M289: MVS Sec.11 p.22
B291: REFERENCE 4 -- Occupancy Master List (dropdown source)
B292: Occupancy Name | C292: Occ. Code | D292: Section | E292: Page | F292: Story Table Section
B293: Storage Warehouses | C293: 406 | D293: 14 | E293: 26 | F293: 14
B294: Distribution Warehouses | C294: 407 | D294: 14 | E294: 23 | F294: 14
...

Sheet Cost Approach
B1: COST APPROACH -- MVS Calculator
B2: Fill in the yellow cells only (Steps 1-3 below, plus the site-improvement/depreciation line items further down). Everything else calculates automatically from the MVS reference tables on the 'M&S Inputs' tab. Your final indicated value appears at the bottom of this sheet.
B3: STEP 1 -- BUILDING IDENTIFICATION
B4: Occupancy Type | C4: Storage Warehouses | I4: Choose the occupancy that best matches the subject improvement.
B5: Occupancy Code / Section / Page (auto) | C5: =IFERROR(INDEX(OCC_CODE,MATCH($C$4,OCC_NAME,0))&" | MVS Sec. "&INDEX(OCC_SECTION,MATCH($C$4,OCC_NAME,0))&" p."&INDEX(OCC_PAGE,MATCH($C$4,OCC_NAME,0)),"")
B6: Building Class | C6: C | I6: A=Fireproofed steel. B=Reinf. concrete. C=Masonry/steel-or-wood frame. D=Wood/combustible (DPOLE=pole-frame). S=Pre-engineered metal. See Class Reference on M&S Inputs.
B7: Quality | C7: Average | I7: Low Cost | Average | Good | Excellent (some occupancies also use Cheap). See Quality Reference on M&S Inputs.
B8: City / Local Area (for Local Multiplier) | C8: Denver | I8: Adams County has no dedicated MVS line -- 'Denver' is the recommended proxy (nearest larger city, per MVS's own guidance); 'Colorado (statewide average)' is the fallback.
B10: STEP 2 -- SIZE, SHAPE & SPRINKLER
B11: Avg Eave / Wall Height (ft) | C11: 18
B12: Area/Perimeter Multiplier Factor 1 | C12: 1 | I12: Look up your building's SF vs. average perimeter in the MVS Floor Area-Perimeter grid for this occupancy's section; enter the two bracketing values here to average.
B13: Area/Perimeter Multiplier Factor 2 | C13: 1
B14: Sprinkler Quality Tier | C14: Average | I14: Independent of building quality -- set to match the actual sprinkler system grade. Section 11 (hotels) has no verified sprinkler table; price manually if needed.
B16: STEP 3 -- APPRAISAL DATE & DE-TREND
B17: Appraisal / Level-of-Value Date | C17: =DATE(2024,6,30) | I17: Colorado's biennial reassessment fixes this at the end of the statutory base period. Current cycle: 7/1/2022-6/30/2024, level of value = 6/30/2024. Update to 6/30/2025 next cycle.
B18: Bracket Quarter - Earlier | C18: Apr 2024 | I18: Pick the two MVS Sec.98 Denver index quarters that straddle the Appraisal Date above (see Denver Index table on M&S Inputs). Rolls the Jan-2025-vintage multipliers below back to your actual valuation date.
B19: Bracket Quarter - Later | C19: Jul 2024
B21: COST APPROACH SUMMARY
B22: Replacement Cost New (RCN) | C22: Area (SF) | D22: $/SF | F22: Subtotal | G22: Total Cost
B23: Building Improvements
B24: Base Cost | C24: ='Property Info'!B5 | D24: =IFERROR(INDEX(BC_VALUE,MATCH($C$4&"~"&$C$6&"~"&$C$7,BC_KEY,0)),"NOT FOUND") | F24: =C24*D24 | I24: =IFERROR("Verified MVS base cost -- "&INDEX(BC_CITE,MATCH($C$4&"~"&$C$6&"~"&$C$7,BC_KEY,0)),"")&" | Area auto-linked to Property Info!B5 (GBA)."
B25: Sprinklers | C25: =C24 | D25: =IFERROR(IF(INDEX(OCC_STORY,MATCH($C$4,OCC_NAME,0))="14",INDEX(SPR14_VALS,MATCH($C$24,SPR14_SF,1),MATCH($C$14,SPR_HDR,0)),IF(INDEX(OCC_STORY,MATCH($C$4,OCC_NAME,0))="13",INDEX(SPR13_VALS,MATCH($C$24,SPR13_SF,1),MATCH($C$14,SPR_HDR,0)),IF(INDEX(OCC_STORY,MATCH($C$4,OCC_NAME,0))="15",INDEX(SPR15_VALS,MATCH($C$24,SPR15_SF,1),MATCH($C$14,SPR_HDR,0)),0))),0) | F25: =C25*D25 | I25: Wet-system cost, by building SF (nearest coverage bracket <= actual SF). Enter 0 manually below if unsprinklered.
B31: Subtotal | F31: =SUM(F24:F30)
B32: Multipliers
B33: Current Cost (de-trended to Appraisal Date) | D33: =IFERROR(INDEX(CCM_VALUES,MATCH(IF($C$6="CMILL","C",IF($C$6="DPOLE","D",IF($C$6="A-B","B",$C$6))),CCM_CLASS,0),MATCH("Sec."&INDEX(OCC_SECTION,MATCH($C$4,OCC_NAME,0)),CCM_SECTIONHDR,0)),"")/IFERROR(INDEX(DEN_VALUES,MATCH($C$18,DEN_LABEL,0),MATCH("Class "&IF($C$6="CMILL","C",IF($C$6="DPOLE","D",IF($C$6="A-B","B",$C$6))),DEN_CLASSHDR,0))+(INDEX(DEN_VALUES,MATCH($C$19,DEN_LABEL,0),MATCH("Class "&IF($C$6="CMILL","C",IF($C$6="DPOLE","D",IF($C$6="A-B","B",$C$6))),DEN_CLASSHDR,0))-INDEX(DEN_VALUES,MATCH($C$18,DEN_LABEL,0),MATCH("Class "&IF($C$6="CMILL","C",IF($C$6="DPOLE","D",IF($C$6="A-B","B",$C$6))),DEN_CLASSHDR,0)))*($C$17-DATEVALUE("1 "&$C$18))/(DATEVALUE("1 "&$C$19)-DATEVALUE("1 "&$C$18)),1) | I33: MVS Sec.99 p.3 Current Cost Multiplier (WESTERN region assumed for Colorado) divided by the Sec.98 Denver de-trend factor for the Appraisal Date -- see Step 3.
B34: Local Area | D34: =IFERROR(INDEX(LAM_VALUES,MATCH($C$8,LAM_CITY,0),MATCH("Class "&IF($C$6="CMILL","C",IF($C$6="DPOLE","D",IF($C$6="A-B","B",$C$6))),LAM_CLASSHDR,0)),"") | I34: MVS Sec.99 p.7 Local Area Multiplier.
B35: Area/Perimeter Multiplier | D35: =AVERAGE(C12:C13)
B36: Story Height (Height entered in Step 2) | D36: =IFERROR(IF(INDEX(OCC_STORY,MATCH($C$4,OCC_NAME,0))="14",INDEX(SH14_M,MATCH($C$11,SH14_H,1)),IF(INDEX(OCC_STORY,MATCH($C$4,OCC_NAME,0))="13",INDEX(SH13_M,MATCH($C$11,SH13_H,1)),IF(INDEX(OCC_STORY,MATCH($C$4,OCC_NAME,0))="15",INDEX(SH15_M,MATCH($C$11,SH15_H,1)),IF(INDEX(OCC_STORY,MATCH($C$4,OCC_NAME,0))="11",INDEX(SH11_M,MATCH($C$11,SH11_H,1)),1)))),1)
B37: Product of Multipliers | F37: =ROUND(PRODUCT(D33:D36),3)
B38: Adjusted Base Building Cost | G38: =F37*F31
B39: Site Improvements (enter your own measured quantities in the Area column)
B40: Parking/Loading Areas (asphalt) | D40: 3.1 | F40: =D40*C40 | I40: MVS Sec.66 p.1, 4-inch asphalt (large areas >3,000 SF), average of low-high range. Enter your own measured SF in the Area column.
B41: Striping (Per Space) | D41: 20 | F41: =D41*C41 | I41: Market-derived; no dedicated MVS table. Enter number of striped spaces in the Area column.
B42: Paving (concrete) | D42: 5.51 | F42: =D42*C42 | I42: MVS Sec.66 p.1, 6-inch concrete (large areas >3,000 SF), average of low-high range.
B43: Other1 | F43: =D43*C43
B44: Other2 | F44: =D44*C44
B45: Landscaping, Lighting, Other Site Improvements | D45: 5.5 | F45: =D45*C45 | I45: MVS Sec.66 landscaping / market estimate. Enter your own measured lot SF in the Area column.
B46: Total Site Improvements | G46: =SUM(F40:F45)
B47: Total Construction Costs | G47: =SUM(G38:G46)
B48: Plus Other Indirect Costs (% of Direct Costs) | C48: 0.1 | G48: =G47*(C48) | I48: Financing, permits, professional fees, insurance during construction. Typical 8-15%.
...

Sheet Construction Costs
B2: Subject's Budgeted Construction Costs
B3: Item | C3: Cost | D3: Cost PSF
B4: Site Inspection, Architectural & Engineering | D4: =C4/'Property Info'!$B$5
B5: Government Fees & Permits | D5: =C5/'Property Info'!$B$5
B6: Site Improvements | D6: =C6/'Property Info'!$B$5
B7: Off-Site Construction | D7: =C7/'Property Info'!$B$5
B8: Vertical Improvements | D8: =C8/'Property Info'!$B$5
B9: Contractor Overhead & Profit | D9: =C9/'Property Info'!$B$5
B10: Inderect Costs | D10: =C10/'Property Info'!$B$5
B11: Total | C11: =SUM(C4:C10) | D11: =C11/'Property Info'!$B$5
F12: Comparable Constrution Cots
F13: Comparable
F14: Location
F15: YOC
F16: Property Type
F17: Total Direct Cost

Sheet Export030823
B1: Property Address | C1: Property City | D1: Account/Parcel | E1: Property Type | F1: Sale Date | G1: Sale Price | H1: Price ($/SF) | I1: Asking Price | J1: DOM | K1: Building SF | L1: Land Area SF | M1: Property Rights Conveyed | N1: Financing | O1: Terms/ Conditions of Sale | P1: Expenditures After Sale | Q1: Market Conditions | R1: Location | S1: Property Size (SF) | T1: YOC / Condition | U1: Quality | V1: Land-To-Building Ratio | W1: Tenancy / Occupancy | X1: Functional Utility | Y1: Total Net Adj. | Z1: Adjusted Price ($/SF)

Sheet Basic Sales Grid
C2: COMPARABLE SALE ADJUSTMENT GRID
D3: Subject | E3: Sale 1 | F3: Sale 2 | G3: Sale 3 | H3: Sale 4 | I3: Sale 5 | J3: Listing 1
C4: Address | D4: =Export030823!B2 | E4: =Export030823!B3 | F4: =Export030823!B4 | G4: =Export030823!B5 | H4: =Export030823!B6 | I4: =Export030823!B7
C5: City, State | D5: =Export030823!C2 | E5: =Export030823!C3 | F5: =Export030823!C4 | G5: =Export030823!C5 | H5: =Export030823!C6 | I5: =Export030823!C7
C6: Parcel Number | D6: =Export030823!D2 | E6: =Export030823!D3 | F6: =Export030823!D4 | G6: =Export030823!D5 | H6: =Export030823!D6 | I6: =Export030823!D7
C7: Property Type | D7: =Export030823!E2 | E7: =Export030823!E3 | F7: =Export030823!E4 | G7: =Export030823!E5 | H7: =Export030823!E6 | I7: =Export030823!E7
C8: Sale Date | D8: N/A | E8: =Export030823!F3 | F8: =Export030823!F4 | G8: =Export030823!F5 | H8: =Export030823!F6 | I8: =Export030823!F7
C9: Sale Price | D9: N/A | E9: =Export030823!G3 | F9: =Export030823!G4 | G9: =Export030823!G5 | H9: =Export030823!G6 | I9: =Export030823!G7
C10: Listing Price | D10: N/A | E10: =Export030823!I3 | F10: =Export030823!I4 | G10: =Export030823!I5 | H10: =Export030823!I6 | I10: =Export030823!I7 | K10: 6769231
C11: Days On Market | D11: N/A | E11: =Export030823!J3 | F11: =Export030823!J4 | G11: =Export030823!J5 | H11: =Export030823!J6 | I11: =Export030823!J7
C12: Data Source | D12: Inspection, Lease, Site Plans, Assessor | E12: CoStar, Assessor, Deed | F12: CoStar, Assessor, Deed | G12: CoStar, Assessor, Deed | H12: CoStar, Assessor, Deed | I12: CoStar, Assessor, Offering Memorandum
C13: Property Size (SF) | D13: =Export030823!K2 | E13: =Export030823!K3 | F13: =Export030823!K4 | G13: =Export030823!K5 | H13: =Export030823!K6 | I13: =Export030823!K7
C14: Site Size (SF) | D14: =Export030823!L2 | E14: =Export030823!L3 | F14: =Export030823!L4 | G14: =Export030823!L5 | H14: =Export030823!L6 | I14: =Export030823!L7
C15: Parking Spaces | D15: 41
C16: Comments
C17: Unadjusted Price Per SF | E17: =E9/E13 | F17: =F9/F13 | G17: =G9/G13 | H17: =H9/H13 | I17: =I9/I13 | K17: =K10/J13
C18: Quantified Adjustments
C19: Sale Type | D19: =Export030823!M2 | E19: =Export030823!M3 | F19: =Export030823!M4 | G19: =Export030823!M5 | H19: =Export030823!M6 | I19: =Export030823!M7 | J19: Leased Fee
C20: Financing | D20: Market Based | E20: =Export030823!N3 | F20: =Export030823!N4 | G20: =Export030823!N5 | H20: =Export030823!N6 | I20: =Export030823!N7
C21: Terms/Conditions of Sale | D21: None | E21: =Export030823!O3 | F21: =Export030823!O4 | G21: =Export030823!O5 | H21: =Export030823!O6 | I21: =Export030823!O7 | J21: Active Listing
C22: Expenditures After Sale | D22: None | E22: =Export030823!P3 | F22: =Export030823!P4 | G22: =Export030823!P5 | H22: =Export030823!P6 | I22: =Export030823!P7
C23: Market Conditions | D23: N/A | E23: =Export030823!Q3 | F23: =Export030823!Q4 | G23: =Export030823!Q5 | H23: =Export030823!Q6 | I23: =Export030823!Q7
C24: Market Conditions Adjusted | E24: =IF(LEFT(CELL("format",E23),1)="P",#REF!*(1+E23),IF(LEFT(CELL("format",E23),1)="C",#REF!+E23)) | F24: =IF(LEFT(CELL("format",F23),1)="P",#REF!*(1+F23),IF(LEFT(CELL("format",F23),1)="C",#REF!+F23)) | G24: =IF(LEFT(CELL("format",G23),1)="P",#REF!*(1+G23),IF(LEFT(CELL("format",G23),1)="C",#REF!+G23)) | H24: =IF(LEFT(CELL("format",H23),1)="P",#REF!*(1+H23),IF(LEFT(CELL("format",H23),1)="C",#REF!+H23)) | I24: =IF(LEFT(CELL("format",I23),1)="P",#REF!*(1+I23),IF(LEFT(CELL("format",I23),1)="C",#REF!+I23))
C25: Total Quantified Adjustment | E25: =SUM(E19:E23) | F25: =SUM(F19:F23) | G25: =SUM(G19:G23) | H25: =SUM(H19:H23) | I25: =SUM(I19:I23)
C26: Quantitatively Adjusted Price | E26: =E17+(E17*E25) | F26: =F17+(F17*F25) | G26: =G17+(G17*G25) | H26: =H17+(H17*H25) | I26: =I17+(I17*I25)
C27: Qualitative Adjustments
C28: =Export030823!R1 | D28: =Export030823!R2 | E28: =Export030823!R3 | F28: =Export030823!R4 | G28: =Export030823!R5 | H28: =Export030823!R6 | I28: =Export030823!R7 | J28: Good
C29: =Export030823!S1 | D29: =Export030823!S2 | E29: =Export030823!S3 | F29: =Export030823!S4 | G29: =Export030823!S5 | H29: =Export030823!S6 | I29: =Export030823!S7 | J29: =J13
C30: =Export030823!T1 | D30: =Export030823!T2 | E30: =Export030823!T3 | F30: =Export030823!T4 | G30: =Export030823!T5 | H30: =Export030823!T6 | I30: =Export030823!T7 | J30: 2019 / Very Good
C31: =Export030823!U1 | D31: =Export030823!U2 | E31: =Export030823!U3 | F31: =Export030823!U4 | G31: =Export030823!U5 | H31: =Export030823!U6 | I31: =Export030823!U7 | J31: Good
C32: =Export030823!V1 | D32: =Export030823!V2 | E32: =Export030823!V3 | F32: =Export030823!V4 | G32: =Export030823!V5 | H32: =Export030823!V6 | I32: =Export030823!V7 | J32: =ROUND((J15/J13)*1000,2)& ":1,000 SF"
C33: =Export030823!W1 | D33: =Export030823!W2 | E33: =Export030823!W3 | F33: =Export030823!W4 | G33: =Export030823!W5 | H33: =Export030823!W6 | I33: =Export030823!W7 | J33: Good
C34: =Export030823!X1 | D34: =Export030823!X2 | E34: =Export030823!X3 | F34: =Export030823!X4 | G34: =Export030823!X5 | H34: =Export030823!X6 | I34: =Export030823!X7 | J34: Good
C35: Total Non Quantified Adj. | E35: =SUM(E28,E29,E30,E31,E32,E33,E34) | F35: =SUM(F28,F29,F30,F31,F32,F33,F34) | G35: =SUM(G28,G29,G30,G31,G32,G33,G34) | H35: =SUM(H28,H29,H30,H31,H32,H33,H34) | I35: =SUM(I28,I29,I30,I31,I32,I33,I34) | K35: =SUM(K28,K29,K30,K31,K32,K33,K34)
C36: Indication for Subject: | E36: =E26+(E26*E35) | F36: =F26+(F26*F35) | G36: =G26+(G26*G35) | H36: =H26+(H26*H35) | I36: =I26+(I26*I35) | K36: =IF(LEFT(CELL("format",K35),1)="P",K26*(1+K35),IF(LEFT(CELL("format",K35),1)="C",K26+K35))
C39: SALES COMPARISON APPROACH VALUE CONCLUSION
C40: Indicated Value per SF
C41: Building Area (SF) | D41: ='Property Info'!B5
C42: =IF(D43=0,"HIDE THIS ROW IF NO DEFERRED MAINTENANCE", "Indicated Value") | D42: =D40*D41
C43: Contract Price | D43: 0
...

Sheet Detailed Sales Grid
C2: COMPARABLE SALE ADJUSTMENT GRID
D3: Subject | E3: Sale 1 | G3: Sale 2 | I3: Sale 3 | K3: Sale 4 | M3: Sale 5 | O3: Listing 1
C4: Address
C5: City, State
C6: Parcel Number
C7: Property Type
C8: Sale Date
C9: Sale Price
C10: Listing Price
C11: Days On Market
C12: Data Source
C13: Property Size (SF)
C14: Site Size (SF)
C15: Parking Spaces
... C59: Indication for Subject:

Sheet LA
B2: LEASE ABSTRACT
B3: Lessor | G3: Annual Rent Calc. Table
B4: Lessee | G4: Month | H4: Monthly Rent
B5: Building Size (SF)
B6: Lease Sign Date
B7: Lease Commencement Date
B8: Lease Expiration Date
B9: Base Lease Term (Months) | C9: =+(C8-C7)/365*12
B10: 12 Months Contract Rental Income (Jan-Dec 2020) | C10: =H17
B11: 12 Months Contract Rental Income (Jan-Dec 2020) | C11: =C10/C5
B12: Base Rents | D12: Annual Rent (Lease)
B13: Year 1 (11/16-10/17) | C13: =D13/$C$5
B14: Year 2 (11/17-10/18) | C14: =D14/$C$5
B15: Year 3 (11/18-10/19) | C15: =D15/$C$5
B16: Year 4 (11/19-10/20) | C16: =D16/$C$5
B17: Year 5 (11/20-10/21) | C17: =D17/$C$5 | G17: Total | H17: =SUM(H5:H16)
B18: Frist Renewal Period | G18: PSF | H18: =H17/FE!C14
B19: Year 6 | C19: =D19/$C$5
B20: Year 7 | C20: =D20/$C$5
B21: Year 8 | C21: =D21/$C$5
B22: Year 9 | C22: =D22/$C$5
B23: Year 10 | C23: =D23/$C$5
B24: Year 11 | C24: =D24/$C$5
B29: Expense Structure | C29: NNN
B30: Landlord Expense Responsibilities
B31: Tenant Expense Responsibilities
B32: Comments
B33: Purchase Options | C33: None
B34: Termination Clause | C34: None
B35: Guarantor | C35: None
B36: Other
B37: Source | C37: Lease Agreement, owner, inspection, assessor data

Sheet LAG Percent
A2: COMPARABLE LEASE ADJUSTMENT GRID
A3: Characteristics | C3: Subject | E3: Lease 1 | G3: Lease 2 | I3: Lease 3 | K3: Lease 4 | M3: Rent 5
A4: Address | C4: ='Property Info'!B17
A5: City | C5: ='Property Info'!B18
A6: Distance from Subject | C6: N/A | E6: 1 mile | G6: 1 mile | I6: 1 mile | K6: 1/4 mile | M6: 1 mile
A7: Data Source | C7: ='Detailed Sales Grid'!D12 | E7: CoStar, Assessor, OM | G7: CoStar, Assessor, OM | I7: CoStar, Assessor, OM | K7: CoStar, Broker, Listing | M7: CoStar, Assessor
A8: Proximity to Subject | C8: N/A | E8: 1.5 miles | G8: 1.5 miles | I8: 1.5 miles | K8: 5.0 miles | M8: 3.0 miles
A9: Building Size | C9: ='Property Info'!B5
A10: Vacancy | D10: =C10/C9 | E10: 0 | F10: 0 | G10: 0 | H10: 0 | I10: 0 | J10: 0 | K10: 0 | L10: 0 | M10: 0 | N10: 0
A11: Parking Ratio | D11: =ROUND((C11/C9)*1000,2)&":1,000SF" | E11: 19 | F11: =ROUND((E11/E9)*1000,2)&":1,000SF" | G11: 19 | H11: =ROUND((G11/G9)*1000,2)&":1,000SF" | I11: 19 | J11: =ROUND((I11/I9)*1000,2)&":1,000SF" | K11: 19 | L11: =ROUND((K11/K9)*1000,2)&":1,000SF" | M11: 19 | N11: =ROUND((M11/M9)*1000,2)&":1,000SF"
A12: Representative Lease
A13: Actual or Asking Lease Rate | C13: N/A | E13: Actual | G13: Actual | I13: Actual | K13: Actual | M13: Actual
A14: Tenant | C14: =LA!C4
A15: SF Area Leased | C15: ='Property Info'!B5 | E15: =E9 | G15: 22248 | I15: 20000 | K15: 37044 | M15: =M9
A16: Commencement
A17: Term | E17: 3 Years | G17: 5 Years | I17: 3 Years | K17: 3 Years | M17: 5 Years
A18: TI Allowance | C18: N/A | E18: N/R | G18: N/R | I18: N/R | K18: N/R | M18: N/R
A19: Lease Rate Expense Structure | C19: NNN | E19: NNN | G19: NNN | I19: NNN | K19: NNN | M19: NNN
A20: Base Annual Rent | C20: =LA!C11
A21: Expense Adjustments | C21: N/A | E21: 0 | G21: 0 | I21: 0 | K21: 0 | M21: 0
A22: Adjusted Rent (NNN) | C22: =C20 | E22: =E20+E21 | G22: =G20+G21 | I22: =I20+I21 | K22: =K20+K21 | M22: =M20+M21
A23: Adjustments | C23: Description | E23: Description | F23: Adj. | G23: Description | H23: Adj. | I23: Description | J23: Adj. | K23: Description | L23: Adj. | M23: Description | N23: Adj.
A24: Market Trends | C24: N/A | E24: =E16 | F24: 0 | G24: =G16 | H24: 0 | I24: =I16 | J24: 0 | K24: =K16 | L24: 0 | M24: =M16 | N24: 0.1
A25: Economics/Tenancy | C25: Industrial, Average Credit Risk | E25: Industrial, Average Credit Risk | F25: 0 | G25: Industrial, Average Credit Risk | H25: 0 | I25: Industrial, Average Credit Risk | J25: 0 | K25: Industrial, Average Credit Risk | L25: 0 | M25: Local Tenant - Good Quality | N25: 0.1
A26: Location | C26: =Export030823!R2 | E26: Average | F26: 0 | G26: Average | H26: 0 | I26: Average | J26: 0 | K26: Average | L26: 0 | N26: 0
A27: Age/Condition | C27: =Export030823!T2 | E27: 1972/Average | F27: 0 | G27: 1971/Fair | H27: 0.1 | I27: 1922 (Ren.)/ Above-Average | J27: -0.05 | K27: 1954/Average | L27: 0 | M27: 2014 (Ren.)/Above-Average | N27: 0.1
A28: Size (SF) | C28: =C15 | E28: =E15 | F28: 0 | G28: =G15 | H28: -0.05 | I28: =I15 | J28: -0.05 | K28: =K15 | L28: 0 | M28: =M15 | N28: -0.05
A29: Quality | C29: =Export030823!U2 | E29: Average | F29: 0 | G29: Average | H29: 0 | I29: Average | J29: 0 | K29: Average | L29: 0 | M29: Good | N29: 0
A30: Land-To-Building Ratio | C30: =Export030823!V2 | E30: =75359/E9 | F30: 0 | G30: =143748/G9 | H30: 0 | I30: =87120/I9 | J30: 0 | K30: =91912/K9 | L30: 0 | M30: 5.52 | N30: -0.05
A31: Functional Utility | C31: =Export030823!X2 | E31: Good: I-3 Zoning | F31: -0.1 | G31: Average | H31: 0 | I31: Above-Average: I-B Zoning | J31: -0.05 | K31: Average | L31: 0 | M31: Average | N31: 0
A32: Subtotal Net Adjustments | F32: =SUM(F24:F31) | H32: =SUM(H24:H31) | J32: =SUM(J24:J31) | L32: =SUM(L24:L31) | N32: =SUM(N24:N31)
A33: Adjusted Lease Rate Per Square Foot | F33: =+E22*(1+F32) | H33: =+G22*(1+H32) | J33: =+I22*(1+J32) | L33: =+K22*(1+L32) | N33: =+M22*(1+N32)
F36: =F33
F37: =H33
F38: =J33
F39: =L33
E41: =(E28-$C$28)/$C$28 | G41: =(G28-$C$28)/$C$28 | I41: =(I28-$C$28)/$C$28 | K41: =(K28-$C$28)/$C$28

Sheet IS Summary
C3: SUMMARY OF IMPROVED SALES
C4: No. | D4: Type | E4: Property Type / Location | F4: Date of Sale | G4: Property Rights | H4: Year Built | I4: Bldg. Size (SF) | J4: Site Size (SF) (Acres) | K4: Building Footprint | L4: Coverage Ratio | M4: Percent Office | N4: Clear Heights (ft.) | O4: Occupancy | P4: Sale Price | Q4: Price PSF | R4: Overall Rate
C5: =ROW()-4 | D5: Sale | O5: Vacant at TOS | P5: 1800000 | Q5: =P5/I5 | R5: N/A
C9: 2 | D9: Sale | O9: Vacant at TOS | P9: 1350000 | Q9: =P9/I9 | R9: N/A
C13: 3 | D13: Sale | O13: Vacant at TOS | P13: 530000 | Q13: =P13/I13 | R13: 0.074
C17: 4 | D17: Sale | O17: Vacant at TOS | P17: 417000 | Q17: =P17/I17 | R17: 0.065
C21: 5 | D21: Sale | O21: Vacant at TOS | P21: 400000 | Q21: =P21/I21 | R21: 0.055
C25: Subj. | E25: ='Property Info'!B15 | H25: ='Property Info'!B8 | I25: ='Property Info'!B5 | J25: ='Property Info'!B11 | K25: ='Property Info'!B5 | L25: ='Property Info'!B13 | M25: ='Property Info'!B14 | N25: ='Property Info'!#REF! | O25: ='Property Info'!B19
E26: ='Property Info'!B16 | J26: ='Property Info'!B12
E27: ='Property Info'!B17

Sheet HOA
C2: HISTORICAL OPERATING ANALYSIS
AA3: =LA!C5
S4: Budget | V4: BBG Projection*
D5: Total | E5: per SF | G5: Total | H5: per SF | J5: Total | K5: per SF | M5: Total | N5: per SF | P5: Total | Q5: per SF | S5: Total | T5: per SF | V5: Total | W5: per SF
C6: Rental Income | D6: =SUMIF(Category,$B6,AMTY1) | E6: =D6/NRA | G6: =SUMIF(Category,$B6,AMTY2) | H6: =G6/NRA | J6: =SUMIF(Category,$B6,AMTY3) | K6: =J6/NRA | N6: =M6/$AA$3 | Q6: =P6/$AA$3 | S6: =SUMIF(Category,$B6,AmtBdgt) | T6: =S6/NRA | V6: =[3]ProForma!C3 | W6: =V6/NRA
C7: Operating Expense Recoveries | D7: =SUMIF(Category,$B7,AMTY1) | E7: =D7/NRA | G7: =SUMIF(Category,$B7,AMTY2) | H7: =G7/NRA | J7: =SUMIF(Category,$B7,AMTY3) | K7: =J7/NRA | N7: =M7/$AA$3 | Q7: =P7/$AA$3 | S7: =SUMIF(Category,$B7,AmtBdgt) | T7: =S7/NRA | V7: =[3]ProForma!C4 | W7: =V7/NRA
C8: Parking | D8: =SUMIF(Category,$B8,AMTY1) | E8: =D8/NRA | G8: =SUMIF(Category,$B8,AMTY2) | H8: =G8/NRA | J8: =SUMIF(Category,$B8,AMTY3) | K8: =J8/NRA | M8: =SUMIF(Category,$B8,AMTY4) | N8: =M8/$AA$3 | P8: =SUMIF(Category,$B8,AMTY5) | Q8: =P8/$AA$3 | S8: =SUMIF(Category,$B8,AmtBdgt) | T8: =S8/NRA | V8: =W8*NRA | W8: 0
C9: Late Charges | D9: =SUMIF(Category,$B9,AMTY1) | E9: =D9/NRA | G9: =SUMIF(Category,$B9,AMTY2) | H9: =G9/NRA | J9: =SUMIF(Category,$B9,AMTY3) | K9: =J9/NRA | M9: =SUMIF(Category,$B9,AMTY4) | N9: =M9/$AA$3 | P9: =SUMIF(Category,$B9,AMTY5) | Q9: =P9/$AA$3 | S9: =SUMIF(Category,$B9,AmtBdgt) | T9: =S9/NRA | V9: =W9*NRA | W9: 0
C10: NSF Fee Income | D10: =SUMIF(Category,$B10,AMTY1) | E10: =D10/NRA | G10: =SUMIF(Category,$B10,AMTY2) | H10: =G10/NRA | J10: =SUMIF(Category,$B10,AMTY3) | K10: =J10/NRA | M10: =SUMIF(Category,$B10,AMTY4) | N10: =M10/$AA$3 | P10: =SUMIF(Category,$B10,AMTY5) | Q10: =P10/$AA$3 | S10: =SUMIF(Category,$B10,AmtBdgt) | T10: =S10/NRA | V10: =W10*NRA | W10: 0
C11: Keys, Lock, Lock Charge | D11: =SUMIF(Category,$B11,AMTY1) | E11: =D11/NRA | G11: =SUMIF(Category,$B11,AMTY2) | H11: =G11/NRA | J11: =SUMIF(Category,$B11,AMTY3) | K11: =J11/NRA | M11: =SUMIF(Category,$B11,AMTY4) | N11: =M11/$AA$3 | P11: =SUMIF(Category,$B11,AMTY5) | Q11: =P11/$AA$3 | S11: =SUMIF(Category,$B11,AmtBdgt) | T11: =S11/NRA | V11: =W11*NRA | W11: 0
C12: Lease Termination Fee Income | D12: =SUMIF(Category,$B12,AMTY1) | E12: =D12/NRA | G12: =SUMIF(Category,$B12,AMTY2) | H12: =G12/NRA | J12: =SUMIF(Category,$B12,AMTY3) | K12: =J12/NRA | M12: =SUMIF(Category,$B12,AMTY4) | N12: =M12/$AA$3 | P12: =SUMIF(Category,$B12,AMTY5) | Q12: =P12/$AA$3 | S12: =SUMIF(Category,$B12,AmtBdgt) | T12: =S12/NRA | V12: =W12*NRA | W12: 0
C13: Legal and Collection Fee Income | D13: =SUMIF(Category,$B13,AMTY1) | E13: =D13/NRA | G13: =SUMIF(Category,$B13,AMTY2) | H13: =G13/NRA | J13: =SUMIF(Category,$B13,AMTY3) | K13: =J13/NRA | M13: =SUMIF(Category,$B13,AMTY4) | N13: =M13/$AA$3 | P13: =SUMIF(Category,$B13,AMTY5) | Q13: =P13/$AA$3 | S13: =SUMIF(Category,$B13,AmtBdgt) | T13: =S13/NRA | V13: =W13*NRA | W13: 0
C14: Storage Space Rental | D14: =SUMIF(Category,$B14,AMTY1) | E14: =D14/NRA | G14: =SUMIF(Category,$B14,AMTY2) | H14: =G14/NRA | J14: =SUMIF(Category,$B14,AMTY3) | K14: =J14/NRA | M14: =SUMIF(Category,$B14,AMTY4) | N14: =M14/$AA$3 | P14: =SUMIF(Category,$B14,AMTY5) | Q14: =P14/$AA$3 | S14: =SUMIF(Category,$B14,AmtBdgt) | T14: =S14/NRA | V14: =W14*NRA | W14: 0
C15: Miscellaneous | D15: =SUMIF(Category,$B15,AMTY1) | E15: =D15/NRA | G15: =SUMIF(Category,$B15,AMTY2) | H15: =G15/NRA | J15: =SUMIF(Category,$B15,AMTY3) | K15: =J15/NRA | M15: =SUMIF(Category,$B15,AMTY4) | N15: =M15/$AA$3 | P15: =SUMIF(Category,$B15,AMTY5) | Q15: =P15/$AA$3 | S15: =SUMIF(Category,$B15,AmtBdgt) | T15: =S15/NRA | V15: =[3]ProForma!C7 | W15: =V15/NRA
C16: Total Potential Gross Income | D16: =SUM(D6:D15) | E16: =D16/NRA | G16: =SUM(G6:G15) | H16: =G16/NRA | J16: =SUM(J6:J15) | K16: =J16/NRA | M16: =SUM(M6:M15) | N16: =M16/$AA$3 | P16: =SUM(P6:P15) | Q16: =P16/$AA$3 | S16: =SUM(S6:S15) | T16: =S16/NRA | V16: =SUM(V6:V15) | W16: =V16/NRA
N17: =M17/$AA$3 | Q17: =P17/$AA$3
C18: Physical Vacancy | D18: =SUMIF(Category,$B18,AMTY1) | E18: =D18/NRA | G18: =SUMIF(Category,$B18,AMTY2) | H18: =G18/NRA | J18: =SUMIF(Category,$B18,AMTY3) | K18: =J18/NRA | M18: =SUMIF(Category,$B18,AMTY4) | N18: =M18/$AA$3 | P18: =SUMIF(Category,$B18,AMTY5) | Q18: =P18/$AA$3 | S18: =SUMIF(Category,$B18,AmtBdgt) | T18: =S18/NRA
C19: Bad Debt / Collection Loss | D19: =SUMIF(Category,$B19,AMTY1) | E19: =D19/NRA | G19: =SUMIF(Category,$B19,AMTY2) | H19: =G19/NRA | J19: =SUMIF(Category,$B19,AMTY3) | K19: =J19/NRA | M19: =SUMIF(Category,$B19,AMTY4) | N19: =M19/$AA$3 | P19: =SUMIF(Category,$B19,AMTY5) | Q19: =P19/$AA$3 | S19: =SUMIF(Category,$B19,AmtBdgt) | T19: =S19/NRA
C20: Concessions | D20: =SUMIF(Category,$B20,AMTY1) | E20: =D20/NRA | G20: =SUMIF(Category,$B20,AMTY2) | H20: =G20/NRA | J20: =SUMIF(Category,$B20,AMTY3) | K20: =J20/NRA | M20: =SUMIF(Category,$B20,AMTY4) | N20: =M20/$AA$3 | P20: =SUMIF(Category,$B20,AMTY5) | Q20: =P20/$AA$3 | S20: =SUMIF(Category,$B20,AmtBdgt) | T20: =S20/NRA
C21: Vacancy & Collection Loss | D21: =-[3]OpActuals!B13 | E21: =D21/NRA | G21: =-[3]OpActuals!C13 | H21: =G21/NRA | J21: =-[3]OpActuals!D13 | K21: =J21/NRA | M21: =-[3]OpActuals!E13 | N21: =M21/$AA$3 | P21: =-[3]OpActuals!G13 | Q21: =P21/$AA$3 | S21: =-[3]OpActuals!H13 | T21: =S21/NRA
C22: EFFECTIVE GROSS INCOME | D22: =D16+D21 | E22: =D22/NRA | G22: =G16+G21 | H22: =G22/NRA | J22: =J16+J21 | K22: =J22/NRA | M22: =SUM(M6:M7) | N22: =M22/$AA$3 | P22: =SUM(P6:P7) | Q22: =P22/$AA$3 | S22: =S16+S21 | T22: =S22/NRA | V22: =[3]ProForma!C11 | W22: =V22/NRA
C23: Fixed Expenses
C24: Real Estate Taxes | D24: =SUMIF(Category,$B24,AMTY1) | E24: =D24/NRA | G24: =SUMIF(Category,$B24,AMTY2) | H24: =G24/NRA | J24: =SUMIF(Category,$B24,AMTY3) | K24: =J24/NRA | N24: =M24/$AA$3 | Q24: =P24/$AA$3 | S24: =SUMIF(Category,$B24,AmtBdgt) | T24: =S24/NRA | V24: =W24*NRA | W24: 0
C25: Property Insurance | D25: =SUMIF(Category,$B25,AMTY1) | E25: =D25/NRA | G25: =SUMIF(Category,$B25,AMTY2) | H25: =G25/NRA | J25: =SUMIF(Category,$B25,AMTY3) | K25: =J25/NRA | N25: =M25/$AA$3 | Q25: =P25/$AA$3 | S25: =SUMIF(Category,$B25,AmtBdgt) | T25: =S25/NRA | V25: =W25*NRA | W25: 0
C26: Variable Expenses
C27: Utilities | D27: =SUMIF(Category,$B27,AMTY1) | E27: =D27/NRA | G27: =SUMIF(Category,$B27,AMTY2) | H27: =G27/NRA | J27: =SUMIF(Category,$B27,AMTY3) | K27: =J27/NRA | N27: =M27/$AA$3 | Q27: =P27/$AA$3 | S27: =SUMIF(Category,$B27,AmtBdgt) | T27: =S27/NRA | V27: =W27*NRA | W27: =[3]SummaryExpenseTbl!M32
C28: CAM Repairs & Maintenance | D28: =SUMIF(Category,$B28,AMTY1) | E28: =D28/NRA | G28: =SUMIF(Category,$B28,AMTY2) | H28: =G28/NRA | J28: =SUMIF(Category,$B28,AMTY3) | K28: =J28/NRA | N28: =M28/$AA$3 | Q28: =P28/$AA$3 | S28: =SUMIF(Category,$B28,AmtBdgt) | T28: =S28/NRA | V28: =W28*NRA | W28: 0
C29: Administrative and General | D29: =SUMIF(Category,$B29,AMTY1) | E29: =D29/NRA | G29: =SUMIF(Category,$B29,AMTY2) | H29: =G29/NRA | J29: =SUMIF(Category,$B29,AMTY3) | K29: =J29/NRA | N29: =M29/$AA$3 | Q29: =P29/$AA$3 | S29: =SUMIF(Category,$B29,AmtBdgt) | T29: =S29/NRA | V29: =W29*NRA | W29: 0
C30: Management | D30: =SUMIF(Category,$B30,AMTY1) | E30: =D30/NRA | G30: =SUMIF(Category,$B30,AMTY2) | H30: =G30/NRA | J30: =SUMIF(Category,$B30,AMTY3) | K30: =J30/NRA | N30: =M30/$AA$3 | Q30: =P30/$AA$3 | S30: =SUMIF(Category,$B30,AmtBdgt) | T30: =S30/NRA | V30: =W30*NRA | W30: =[3]SummaryExpenseTbl!M38
C31: Replacement Reserves | D31: =SUMIF(Category,$B31,AMTY1) | E31: =D31/NRA | G31: =SUMIF(Category,$B31,AMTY2) | H31: =G31/NRA | J31: =SUMIF(Category,$B31,AMTY3) | K31: =J31/NRA | M31: =SUMIF(Category,$B31,AMTY4) | N31: =M31/$AA$3 | P31: =SUMIF(Category,$B31,AMTY5) | Q31: =P31/$AA$3 | S31: =SUMIF(Category,$B31,AmtBdgt) | T31: =S31/NRA | V31: =W31*NRA | W31: =[3]SummaryExpenseTbl!M41
C33: TOTAL EXPENSES | D33: =SUM(#REF!,#REF!, D27, D28,D29,D30, D31) | E33: =D33/NRA | G33: =SUM(#REF!,#REF!, G27, G28,G29,G30, G31) | H33: =G33/NRA | J33: =SUM(#REF!,#REF!, J27, J28,J29,J30, J31) | K33: =J33/NRA | M33: =SUM(M24:M25,M27:M30) | N33: =M33/$AA$3 | P33: =SUM(P24:P25,P27:P30) | Q33: =P33/$AA$3 | S33: =SUM(#REF!,#REF!, S27, S28,S29,S30, S31) | T33: =S33/NRA | V33: =SUM(#REF!,#REF!, V27,#REF!, V30, V31) | W33: =V33/NRA
C35: NET OPERATING INCOME (NOI) | D35: =D22-D33 | E35: =D35/NRA | G35: =G22-G33 | H35: =G35/NRA | J35: =J22-J33 | K35: =J35/NRA | M35: =M22-M33 | N35: =M35/$AA$3 | P35: =P22-P33 | Q35: =P35/$AA$3 | S35: =S22-S33 | T35: =S35/NRA | V35: =V22-V33 | W35: =V35/NRA

Sheet CED
D2: COMPARABLE EXPENSES DATA
D3: Comparable No. | E3: 1 | H3: 2 | K3: 3 | N3: 3
D4: City
D5: Year Built
D6: Rentable Area | T6: Cmp1 | U6: Cmp2 | V6: Cmp3 | W6: Cmp4 | X6: Min | Y6: Max | AA6: Range | AB6: Avg
D7: Year Operations | E7: 2016 | F7: 2019 | H7: 2016 | I7: 2020 | K7: 2016 | L7: 2020 | N7: 2016
D8: Occupancy | E8: 1 | F8: 1 | H8: 1 | I8: 1 | K8: 1 | L8: 1 | N8: 1
D9: Expenses
D10: Real Estate Taxes | O10: =N10/N6 | Q10: =AVERAGE(F10,I10,L10) | T10: =F10 | U10: =I10 | V10: =L10 | W10: =IF(ISERROR(Q24),"",IF(Q24=0,"",Q24)) | X10: =MIN(T10:W10) | Y10: =MAX(T10:W10) | AA10: =IF(X10=Y10,TEXT(X10,"$0.00;;-"),CONCATENATE(TEXT(X10,"$0.00;;-"),"–",TEXT(Y10,"$0.00;;-"))) | AB10: =AVERAGE(T10:W10)
D11: Insurance | O11: =N11/N6 | Q11: =AVERAGE(F11,I11,L11) | T11: =F11 | U11: =I11 | V11: =L11 | W11: =IF(ISERROR(Q25),"",IF(Q25=0,"",Q25)) | X11: =MIN(T11:W11) | Y11: =MAX(T11:W11) | AA11: =IF(X11=Y11,TEXT(X11,"$0.00;;-"),CONCATENATE(TEXT(X11,"$0.00;;-"),"–",TEXT(Y11,"$0.00;;-"))) | AB11: =AVERAGE(T11:W11)
D12: Utilities | O12: =N12/N6 | T12: =F12 | U12: =I12 | V12: =L12 | W12: =IF(ISERROR(Q26),"",IF(Q26=0,"",Q26)) | X12: =MIN(T12:W12) | Y12: =MAX(T12:W12) | AA12: =IF(X12=Y12,TEXT(X12,"$0.00;;-"),CONCATENATE(TEXT(X12,"$0.00;;-"),"–",TEXT(Y12,"$0.00;;-"))) | AB12: =AVERAGE(T12:W12)
